<mujoco>
  <compiler autolimits="true" angle="degree"/>
  <!-- <option timestep="0.005" gravity="0 0 0"/> -->
  <option timestep="0.002" gravity="0 0 -9.81"/>
  <visual>
    <global offwidth="1920" offheight="1080"/>
  </visual>

  <asset>
    <texture name="grid" type="2d" builtin="checker" width="512" height="512" rgb1=".1 .2 .3" rgb2=".2 .3 .4"/>
    <material name="grid" texture="grid" texrepeat="1 1" texuniform="true" reflectance=".2"/>
    <mesh name="motor" file="stl/RDS3235.stl" scale=".01 .01 .01"/>
    <mesh name="large_C" file="stl/35_Large_C.stl" scale=".01 .01 .01"/>
    <mesh name="small_C" file="stl/Small_C.obj" scale=".01 .01 .01"/>
    <mesh name="box" file="stl/box.stl" scale=".01 .01 .01"/>
    <mesh name="box_cap" file="stl/box_cap.stl" scale=".01 .01 .01"/>
    <mesh name="crown" file="stl/crown_holder_v1.stl" scale=".01 .01 .01"/>
    <mesh name="f_cdisc" file="stl/clip_disc.stl" scale=".01 .01 .01"/>
    <mesh name="m_cdisc" file="stl/clip_disc_mate.stl" scale=".01 .01 .01"/>
  </asset>

  <default>
    <joint damping="7"/>
    <geom friction="1.0 0.002 0.3"/>
  </default>

  <worldbody>
   <site name="origin" pos="0 0 0"/>

    <camera name="fixed_cam" pos="-0.6 -8 15" xyaxes="1 0 0 0 1 0"/>
    <camera name="tracking_cam" pos="0 0 15" mode="trackcom" xyaxes="1 0 0 0 1 0"/>

    <!-- <geom name="floor" type="plane" size="100 100 .01" rgba="1 1 1 1"/> -->
    <geom name="floor" pos="0 0 0" type="plane" material="grid" size="100 100 .01" rgba="1 1 1 1"/>

    <light name="spotlight" mode="targetbodycom" castshadow="true" directional="true" target="snake" diffuse=".8 .8 .8" specular="0.3 0.3 0.3" pos="0 -6 4" cutoff="30"/>
    <!-- <light name="top" pos="0 0 2" mode="trackcom"/> -->
    <!-- <body name="snake" pos="-2.5 0 0.407" euler="90 180 180"> -->
    <body name="snake" pos="-2.5 2 0.205"> <!-- Weight: 130 grams -->
      <freejoint/>
      <!-- <joint type="hinge" axis="1 0 0"/> -->
      <geom type="mesh" mesh="motor" pos="0 -0.01 0.01" euler="90 90 0" rgba="0.2 0.2 0.2 1" mass="0.110" />
      <geom type="mesh" mesh="crown" pos="0.13 -0.01 0.109" euler="90 0 90" rgba="1 0.65 0 1" mass="0.015" />
      <geom type="mesh" mesh="f_cdisc" pos="-0.35 0.1 0.11" euler="0 0 90"  rgba="1 0.65 0 1" mass="0.01" />
      <body name="m1" pos="0.65 0.0 0.1" euler="180 0 180"> <!-- Weight: 20 grams -->
        <joint name="m1" axis="1 0 0" type="hinge" pos="0.8 0.1 -0.01" limited="true" range="-135 135" />
        <geom type="mesh" mesh="large_C" pos="0 0 0" mass="0.015"/>
        <geom type="mesh" mesh="large_C" pos="0.67 -0.01 -0.107" euler="90 90 0" mass="0.015"/>
        <body name="m3_r" pos="0.0 -0.01 0" euler="0 0 0"> <!-- Weight: 330 grams -->
          <joint name="m2" type="hinge" axis="0 0 1" pos="0.11 0.1 -0.2" limited="true" range="-135 135"/>
          <geom type="mesh" mesh="motor" rgba="0.2 0.2 0.2 1" mass="0.02"/>
          <geom type="mesh" mesh="box_cap" pos="-0.304 0.1 0" euler="90 0 -90" rgba="1 0.65 0 1" mass="0.01"/>
          <geom type="mesh" mesh="box" pos="-0.904 0.1 0" euler="90 0 -90" rgba="1 0.65 0 1" mass="0.270"/>
          <geom type="mesh" mesh="box_cap" pos="-1.504 0.1 0" euler="0 0 90" rgba="1 0.65 0 1" mass="0.01"/>
          <geom type="mesh" mesh="motor" pos="-1.803 0.1 -0.1" euler="90 180 0" rgba="0.2 0.2 0.2 1" mass="0.02"/>
          <body name="m4_r" pos="-1.8 0.086 0.1" euler="90 0 180"> <!-- Weight: 380 grams -->
            <joint name="m3" axis="0 0 1" type="hinge" pos="0.11 0.1 -0.2" limited="true" range="-135 135" />
            <geom type="mesh" mesh="large_C" pos="0 0 0" mass="0.02"/>
            <geom type="mesh" mesh="box_cap" pos="0.404 0.1 0" euler="90 0 90" rgba="1 0.65 0 1" mass="0.02" />
            <!-- <geom type="mesh" mesh="box" pos="1.004 0.1 0" euler="90 0 -90" rgba="1 1 0 1" friction="8.9 1.5 1.4"/> -->
            <!-- <geom type="mesh" mesh="box_cap" pos="1.604 0.1 0" euler="0 180 90"  friction="8.9 1.5 1.4"/> -->
            <geom type="mesh" mesh="box" pos="1.004 0.1 0" euler="90 0 -90" rgba="1 0.65 0 1" mass="0.300" />
            <geom type="mesh" mesh="box_cap" pos="1.604 0.1 0" euler="0 180 90" rgba="1 0.65 0 1" mass="0.02"/>
            <geom type="mesh" mesh="motor" pos="1.903 0.1 -0.1" euler="90 0 0" rgba="0.2 0.2 0.2 1" mass="0.02" />
            <body name="m5_r" pos="1.9 0.1 -0.1" euler="90 0 0"> <!-- Weight: 20 grams -->
              <joint name="m4" type="hinge" pos="0.11 0.1 -0.2" limited="true" range="-135 135"/>
              <!-- <geom type="mesh" mesh="large_C" pos="0 0 0" friction="0.1 1.5 1.5"/> -->
              <!-- <geom type="mesh" mesh="large_C" pos="0.67 0.21 0.09" euler="-90 90 0" friction="0.1 1.5 1.5"/> -->
              <geom type="mesh" mesh="large_C" pos="0 0 0" mass="0.01"/>
              <geom type="mesh" mesh="large_C" pos="0.67 0.21 0.09" euler="-90 90 0" mass="0.01" />
              <!-- <geom type="mesh" mesh="large_C" pos="0 0 0" /> -->
              <!-- <geom type="mesh" mesh="large_C" pos="0.67 0.21 0.09" euler="-90 90 0" /> -->
              <body name="m6_r" pos="0.65 0.2 -0.115" euler="0 0 180"> <!-- Weight: 145 grams -->
                <joint name="m5" type="hinge" axis="1 0 0" pos="-0.1 0.1 0.11" limited="true" range="-135 135" />
                <!-- <geom type="mesh" mesh="motor" pos="0 -0.01 0.01" euler="90 90 0" friction="0.1 1.5 1.5"/> -->
                <!-- <geom name="g_foot1_1" type="mesh" mesh="crown" pos="0.13 -0.01 0.109" euler="90 0 90" friction="0.1 1.5 1.5"/> -->
                <!-- <geom name="g_foot1_2" type="mesh" mesh="m_cdisc" pos="-0.37 0.1 0.1" euler="0 0 -90" rgba="0.8 0 0 1" friction="0.1 1.5 1.5"/> -->
                <geom type="mesh" mesh="motor" pos="0 -0.01 0.01" euler="90 90 0" rgba="0.2 0.2 0.2 1" mass="0.125"/>
                <geom name="g_foot1_1" type="mesh" mesh="crown" pos="0.13 -0.01 0.109" euler="90 0 90" rgba="1 0.65 0 1" mass="0.01"/>
                <geom name="g_foot1_2" type="mesh" mesh="m_cdisc" pos="-0.37 0.1 0.1" euler="0 0 -90" rgba="1 0.65 0 1" mass="0.01"/>
              </body>
            </body>
          </body>
        </body>
      </body>
    </body>
  </worldbody>

  <actuator>
    <position name="m1_act" joint="m1" kp="60" ctrllimited="false" forcelimited="true" ctrlrange="-1 1" forcerange="-15 15"/>
    <position name="m2_act" joint="m2" kp="60" ctrllimited="false" forcelimited="true" ctrlrange="-1 1" forcerange="-15 15"/>
    <position name="m3_act" joint="m3" kp="60" ctrllimited="false" forcelimited="true" ctrlrange="-1 1" forcerange="-15 15"/>
    <position name="m4_act" joint="m4" kp="60" ctrllimited="false" forcelimited="true" ctrlrange="-1 1" forcerange="-15 15"/>
    <position name="m5_act" joint="m5" kp="60" ctrllimited="false" forcelimited="true" ctrlrange="-1 1" forcerange="-15 15"/>
  </actuator>

  <sensor>
    <framepos name="distance_from_origin" objtype="body" objname="m4_r" reftype="site" refname="origin"/>
    <frameangvel name="rx" objtype="body" objname="m4_r"/>
    <!-- <framequat name="IMU" objtype="body" objname="m4_r"/> -->
    <jointpos name="m1_act" joint="m1"/>
    <jointpos name="m2_act" joint="m2"/>
    <jointpos name="m3_act" joint="m3"/>
    <jointpos name="m4_act" joint="m4"/>
    <jointpos name="m5_act" joint="m5"/>
  </sensor>

</mujoco>
