<mujoco>
  <compiler autolimits="true"/>
  <option timestep="0.02" gravity="0 0 -9.81"/>

  <asset>
    <texture name="grid" type="2d" builtin="checker" width="512" height="512" rgb1=".1 .2 .3" rgb2=".2 .3 .4"/>
    <material name="grid" texture="grid" texrepeat="1 1" texuniform="true" reflectance=".2"/>
    <mesh name="motor" file="stl/RDS3235.stl" scale=".01 .01 .01" />
    <mesh name="large_C" file="stl/35_Large_C.stl" scale=".01 .01 .01"/>
    <mesh name="small_C" file="stl/Small_C.obj" scale=".01 .01 .01"/>
    <mesh name="box" file="stl/box.stl" scale=".01 .01 .01"/>
    <mesh name="box_cap" file="stl/box_cap.stl" scale=".01 .01 .01"/>
    <mesh name="crown" file="stl/crown_holder_v1.stl" scale=".01 .01 .01"/>
    <mesh name="f_cdisc" file="stl/clip_disc.stl" scale=".01 .01 .01"/>
    <mesh name="m_cdisc" file="stl/clip_disc_mate.stl" scale=".01 .01 .01"/>
  </asset>

  <default>
    <joint damping="20"/>
    <geom  density="1000"/>
    <position  kv="6" ctrllimited="true" forcelimited="true" ctrlrange="-1.57 1.57"/>
  </default>

  <worldbody>
    <camera name="fixed_cam" pos="-0.6 -6 28" xyaxes="1 0 0 0 1 0"/>
    <camera name="tracking_cam" pos="0 0  28" mode="trackcom" xyaxes="1 0 0 0 1 0"/>
    <body name="floor">
      <geom name="g_floor" type="plane" size="100 100 .01" rgba="1 1 1 1"/>
      <!-- <geom name="g_floor" type="plane" size="9 9 .01" material="grid"/> -->
    </body>
    <light name="spotlight" mode="targetbodycom" castshadow="false" directional="true" target="m1_r" diffuse=".8 .8 .8" specular="0.3 0.3 0.3" pos="0 -6 4" cutoff="30"/>
    <body name="main_box" pos="0 0 0.5" euler="45 0 0">
      <geom name="g_main_box" type="box" size="0.01 0.01 0.01" euler="0 180 0" />
        <freejoint/>
        <body name="m1_r" pos="0.4 0.1 0.1" euler="0 180 180">
          <geom type="mesh" mesh="motor" pos="0 -0.01 0.01" euler="90 90 0" mass="1.2" rgba="0.2 0.2 0.2 1"/>
          <geom type="mesh" mesh="crown" pos="0.13 -0.01 0.109" euler="90 0 90" mass="0.15"/>
          <geom type="mesh" mesh="f_cdisc" pos="-0.35 0.1 0.11" euler="0 0 90" rgba="1 0.65 0 1" mass="0.1"/>
          <body name="m2_r" pos="0.65 0.0 0.1" euler="180 0 180" >
            <joint name="m1_right" axis="-1 0 0" type="hinge" pos="0.8 0.1 -0.01" limited="true" range="-90 90" />
            <geom type="mesh" mesh="large_C" pos="0 0 0" mass="0.1"/>
            <geom type="mesh" mesh="large_C" pos="0.67 -0.01 -0.107" euler="90 90 0" mass="0.1"/>
            <body name="m3_r" pos="0.0 -0.01 0" euler="0 0 0">
              <joint name="m2_right" type="hinge" axis="0 0 1" pos="0.11 0.1 -0.2" limited="true" range="-135 135"/>
              <geom type="mesh" mesh="motor" mass="1.2" rgba="0.2 0.2 0.2 1" />
              <geom type="mesh" mesh="box_cap" pos="-0.304 0.1 0" euler="90 0 -90" mass="0.1" rgba="1 0.65 0 1"/>
              <geom type="mesh" mesh="box" pos="-0.904 0.1 0" euler="90 0 -90" mass="0.25" rgba="1 0.65 0 1"/>
              <geom type="mesh" mesh="box_cap" pos="-1.504 0.1 0" euler="0 0 90" mass="0.1" rgba="1 0.65 0 1"/>
              <geom type="mesh" mesh="motor" pos="-1.803 0.1 -0.1" euler="90 180 0" mass="1.2" rgba="0.2 0.2 0.2 1"/>
              <body name="m4_r" pos="-1.8 0.086 0.1" euler="90 0 180">
                <joint name="m3_right" type="hinge" pos="0.11 0.1 -0.2" limited="true" range="-90 90" />
                <geom type="mesh" mesh="large_C" pos="0 0 0" mass="0.1"/>
                <geom type="mesh" mesh="box_cap" pos="0.404 0.1 0" euler="90 0 90" mass="0.1" rgba="1 0.65 0 1"/>
                <geom type="mesh" mesh="box" pos="1.004 0.1 0" euler="90 0 -90" mass="0.25" rgba="1 0.65 0 1"/>
                <geom type="mesh" mesh="box_cap" pos="1.604 0.1 0" euler="0 180 90" mass="0.1" rgba="1 0.65 0 1"/>
                <geom type="mesh" mesh="motor" pos="1.903 0.1 -0.1" euler="90 0 0" mass="1.2"  rgba="0.2 0.2 0.2 1"/>
                <body name="m5_r" pos="1.9 0.1 -0.1" euler="90 0 0">
                  <joint name="m4_right" type="hinge" pos="0.11 0.1 -0.2" limited="true" range="-90 90"/>
                  <geom type="mesh" mesh="large_C" pos="0 0 0" mass="0.1"/>
                  <geom type="mesh" mesh="large_C" pos="0.67 -0.01 -0.107" euler="90 90 0" mass="0.1"/>
                  <body name="m6_r" pos="0.67 0.0 0.1" euler="180 0 180">
                    <joint name="m5_right" type="hinge" axis="1 0 0" pos="-0.1 0.1 0.11" limited="true" range="-90 90"/>
                    <geom type="mesh" mesh="motor" pos="0 -0.01 0.01" euler="90 90 0" mass="1.2" rgba="0.2 0.2 0.2 1"/>
                    <geom name="g_foot1_1" type="mesh" mesh="crown" pos="0.13 -0.01 0.109" euler="90 0 90" mass="0.15" rgba="1 0.65 0 1"/>
                    <geom name="g_foot1_2" type="mesh" mesh="m_cdisc" pos="-0.37 0.1 0.1" euler="0 0 -90" rgba="1 0.65 0 1" priority="2" margin=".03" gap=".03" mass="0.1"/>
                  </body>
                </body>
              </body>
            </body>
          </body>
        </body>
        <body name="m1_l" pos="-0.45 0.1 -0.1" euler="180 180 0">
          <geom type="mesh" mesh="motor" pos="0 -0.01 0.01" euler="90 90 0" mass="1.2"/>
          <geom type="mesh" mesh="crown" pos="0.13 -0.01 0.109" euler="90 0 90" mass="0.1" rgba="1 0.65 0 1"/>
          <geom  type="mesh" mesh="m_cdisc" pos="-0.37 0.1 0.1" euler="0 0 -90" rgba="1 0.65 0 1" priority="2" margin=".03" gap=".03" mass="0.1"/>
          <body name="m2_l" pos="0.65 0.0 0.1" euler="180 0 180">
            <joint name="m1_left" axis="-1 0 0" type="hinge"  pos="0.8 0.1 -0.01" limited="true" range="-90 90"/>
            <geom type="mesh" mesh="large_C" pos="0 0 0" mass="0.1"/>
            <geom type="mesh" mesh="large_C" pos="0.67 -0.01 -0.107" euler="90 90 0" mass="0.1"/>
            <body name="m3_l" pos="0.0 -0.01 0" euler="0 0 0" >
              <joint name="m2_left" type="hinge" axis="0 0 -1" pos="0.11 0.1 -0.2" limited="true" range="-135 135"/>
              <geom type="mesh" mesh="motor" mass="1.2"/>
              <geom type="mesh" mesh="box_cap" pos="-0.304 0.1 0" euler="90 0 -90" mass="0.1" rgba="1 0.65 0 1"/>
              <geom type="mesh" mesh="box" pos="-0.904 0.1 0" euler="90 0 -90" mass="0.25" rgba="1 0.65 0 1"/>
              <geom type="mesh" mesh="box_cap" pos="-1.504 0.1 0" euler="0 0 90" mass="0.1" rgba="1 0.65 0 1"/>
              <geom type="mesh" mesh="motor" pos="-1.803 0.1 -0.1" euler="90 180 0" mass="1.2"/>
              <body name="m4_l" pos="-1.8 0.086 0.1" euler="90 0 180">
                <joint name="m3_left" type="hinge" pos="0.11 0.1 -0.2" limited="true" range="-90 90" />
                <geom type="mesh" mesh="large_C" pos="0 0 0" mass="0.1"/>
                <geom type="mesh" mesh="box_cap" pos="0.404 0.1 0" euler="90 0 90" mass="0.1" rgba="1 0.65 0 1"/>
                <geom type="mesh" mesh="box" pos="1.004 0.1 0" euler="90 0 -90" mass="0.25" rgba="1 0.65 0 1"/>
                <geom type="mesh" mesh="box_cap" pos="1.604 0.1 0" euler="0 180 90" mass="0.1" rgba="1 0.65 0 1"/>
                <geom type="mesh" mesh="motor" pos="1.903 0.1 -0.1" euler="90 0 0" mass="1.2"/>
                <body name="m5_l" pos="1.9 0.1 -0.1" euler="90 0 0">
                  <joint name="m4_left" type="hinge" pos="0.11 0.1 -0.2" limited="true" range="-90 90"/>
                  <geom type="mesh" mesh="large_C" pos="0 0 0" mass="0.1"/>
                  <geom type="mesh" mesh="large_C" pos="0.67 -0.01 -0.107" euler="90 90 0" mass="0.1"/>
                  <body name="m6_l" pos="0.67 0.0 0.1" euler="180 0 180">
                    <joint name="m5_left" type="hinge" axis="1 0 0" pos="-0.1 0.1 0.11" limited="true" range="-90 90"/>
                    <geom type="mesh" mesh="motor" pos="0 -0.01 0.01" euler="90 90 0" mass="1.2"/>
                    <geom name="g_foot2_1" type="mesh" mesh="crown" pos="0.13 -0.01 0.109" euler="90 0 90" mass="0.15" rgba="1 0.65 0 1"/>
                    <geom  name="g_foot2_2" type="mesh" mesh="f_cdisc" pos="-0.35 0.1 0.11" euler="0 0 90" rgba="1 0.65 0 1" mass="0.1"/>
                  </body>
                </body>
              </body>
            </body>
          </body>
        </body>

    </body>
</worldbody>

<actuator>
    <position name="m1_r_act" joint="m1_right" kp="90" forcerange="-175 175"/>
    <position name="m2_r_act" joint="m2_right" kp="120" forcerange="-375 375"/>
    <position name="m3_r_act" joint="m3_right" kp="300" forcerange="-500 500"/>
    <position name="m4_r_act" joint="m4_right" kp="120" forcerange="-175 175"/>
    <position name="m5_r_act" joint="m5_right" kp="90" forcerange="-175 175"/>

    <position name="m1_l_act" joint="m1_left" kp="90" forcerange="-275 275"/>
    <position name="m2_l_act" joint="m2_left" kp="120" forcerange="-375 375"/>
    <position name="m3_l_act" joint="m3_left" kp="300" forcerange="-500 500"/>
    <position name="m4_l_act" joint="m4_left" kp="120" forcerange="-275 275"/>
    <position name="m5_l_act" joint="m5_left" kp="90" forcerange="-275 275"/>
</actuator>

<sensor>
    <jointpos joint="m1_right"/>
    <jointpos joint="m2_right"/>
    <jointpos joint="m3_right"/>
    <jointpos joint="m4_right"/>
    <jointpos joint="m5_right"/>

    <jointpos joint="m1_left"/>
    <jointpos joint="m2_left"/>
    <jointpos joint="m3_left"/>
    <jointpos joint="m4_left"/>
    <jointpos joint="m5_left"/>
</sensor>


<contact>
    <pair geom1="g_foot1_1" geom2="g_floor" friction="3.5 1.5 0.005 0.0001 0.0001" />
    <pair geom1="g_foot1_2" geom2="g_floor" friction="3.5 1.5 0.005 0.0001 0.0001" />
    <pair geom1="g_foot2_1" geom2="g_floor" friction="3.5 1.5 0.005 0.0001 0.0001" />
    <pair geom1="g_foot2_2" geom2="g_floor" friction="3.5 1.5 0.005 0.0001 0.0001" />

    <!-- <exclude body1="freebody_l" body2="floor"/> -->
    <!-- <exclude body1="freebody_r" body2="floor"/> -->
</contact>

</mujoco>
